2023-10-10 00:25:54,930 ERROR 12187 nodejs.ClusterClientNoResponseError: client no response in 1074853ms exceeding maxIdleTime 60000ms, maybe the connection is close on other side.
    at Timeout._onTimeout (/Users/xujiashuang/Desktop/bigdata-server/node_modules/_cluster-client@3.5.0@cluster-client/lib/leader.js:79:25)
    at listOnTimeout (node:internal/timers:564:17)
    at process.processTimers (node:internal/timers:507:7)
name: "ClusterClientNoResponseError"
pid: 12187
hostname: xjswwdeMBP

2023-10-10 00:41:08,948 ERROR 12187 nodejs.ClusterClientNoResponseError: client no response in 913926ms exceeding maxIdleTime 60000ms, maybe the connection is close on other side.
    at Timeout._onTimeout (/Users/xujiashuang/Desktop/bigdata-server/node_modules/_cluster-client@3.5.0@cluster-client/lib/leader.js:79:25)
    at listOnTimeout (node:internal/timers:564:17)
    at process.processTimers (node:internal/timers:507:7)
name: "ClusterClientNoResponseError"
pid: 12187
hostname: xjswwdeMBP

2023-10-10 00:58:03,959 ERROR 12187 nodejs.ClusterClientNoResponseError: client no response in 1014928ms exceeding maxIdleTime 60000ms, maybe the connection is close on other side.
    at Timeout._onTimeout (/Users/xujiashuang/Desktop/bigdata-server/node_modules/_cluster-client@3.5.0@cluster-client/lib/leader.js:79:25)
    at listOnTimeout (node:internal/timers:564:17)
    at process.processTimers (node:internal/timers:507:7)
name: "ClusterClientNoResponseError"
pid: 12187
hostname: xjswwdeMBP

2023-10-10 01:11:30,943 ERROR 12187 nodejs.ClusterClientNoResponseError: client no response in 806950ms exceeding maxIdleTime 60000ms, maybe the connection is close on other side.
    at Timeout._onTimeout (/Users/xujiashuang/Desktop/bigdata-server/node_modules/_cluster-client@3.5.0@cluster-client/lib/leader.js:79:25)
    at listOnTimeout (node:internal/timers:564:17)
    at process.processTimers (node:internal/timers:507:7)
name: "ClusterClientNoResponseError"
pid: 12187
hostname: xjswwdeMBP

2023-10-10 01:27:58,891 ERROR 12187 nodejs.ClusterClientNoResponseError: client no response in 987946ms exceeding maxIdleTime 60000ms, maybe the connection is close on other side.
    at Timeout._onTimeout (/Users/xujiashuang/Desktop/bigdata-server/node_modules/_cluster-client@3.5.0@cluster-client/lib/leader.js:79:25)
    at listOnTimeout (node:internal/timers:564:17)
    at process.processTimers (node:internal/timers:507:7)
name: "ClusterClientNoResponseError"
pid: 12187
hostname: xjswwdeMBP

2023-10-10 01:33:53,929 ERROR 12187 nodejs.ClusterClientNoResponseError: client no response in 355034ms exceeding maxIdleTime 60000ms, maybe the connection is close on other side.
    at Timeout._onTimeout (/Users/xujiashuang/Desktop/bigdata-server/node_modules/_cluster-client@3.5.0@cluster-client/lib/leader.js:79:25)
    at listOnTimeout (node:internal/timers:564:17)
    at process.processTimers (node:internal/timers:507:7)
name: "ClusterClientNoResponseError"
pid: 12187
hostname: xjswwdeMBP

2023-10-10 02:06:25,149 ERROR 12187 nodejs.ClusterClientNoResponseError: client no response in 956639ms exceeding maxIdleTime 60000ms, maybe the connection is close on other side.
    at Timeout._onTimeout (/Users/xujiashuang/Desktop/bigdata-server/node_modules/_cluster-client@3.5.0@cluster-client/lib/leader.js:79:25)
    at listOnTimeout (node:internal/timers:564:17)
    at process.processTimers (node:internal/timers:507:7)
name: "ClusterClientNoResponseError"
pid: 12187
hostname: xjswwdeMBP

2023-10-10 02:23:25,156 ERROR 12187 nodejs.ClusterClientNoResponseError: client no response in 1020002ms exceeding maxIdleTime 60000ms, maybe the connection is close on other side.
    at Timeout._onTimeout (/Users/xujiashuang/Desktop/bigdata-server/node_modules/_cluster-client@3.5.0@cluster-client/lib/leader.js:79:25)
    at listOnTimeout (node:internal/timers:564:17)
    at process.processTimers (node:internal/timers:507:7)
name: "ClusterClientNoResponseError"
pid: 12187
hostname: xjswwdeMBP

2023-10-10 02:39:28,166 ERROR 12187 nodejs.ClusterClientNoResponseError: client no response in 963008ms exceeding maxIdleTime 60000ms, maybe the connection is close on other side.
    at Timeout._onTimeout (/Users/xujiashuang/Desktop/bigdata-server/node_modules/_cluster-client@3.5.0@cluster-client/lib/leader.js:79:25)
    at listOnTimeout (node:internal/timers:564:17)
    at process.processTimers (node:internal/timers:507:7)
name: "ClusterClientNoResponseError"
pid: 12187
hostname: xjswwdeMBP

2023-10-10 02:57:28,140 ERROR 12187 nodejs.ClusterClientNoResponseError: client no response in 1079973ms exceeding maxIdleTime 60000ms, maybe the connection is close on other side.
    at Timeout._onTimeout (/Users/xujiashuang/Desktop/bigdata-server/node_modules/_cluster-client@3.5.0@cluster-client/lib/leader.js:79:25)
    at listOnTimeout (node:internal/timers:564:17)
    at process.processTimers (node:internal/timers:507:7)
name: "ClusterClientNoResponseError"
pid: 12187
hostname: xjswwdeMBP

2023-10-10 03:12:34,163 ERROR 12187 nodejs.ClusterClientNoResponseError: client no response in 906020ms exceeding maxIdleTime 60000ms, maybe the connection is close on other side.
    at Timeout._onTimeout (/Users/xujiashuang/Desktop/bigdata-server/node_modules/_cluster-client@3.5.0@cluster-client/lib/leader.js:79:25)
    at listOnTimeout (node:internal/timers:564:17)
    at process.processTimers (node:internal/timers:507:7)
name: "ClusterClientNoResponseError"
pid: 12187
hostname: xjswwdeMBP

2023-10-10 03:30:29,149 ERROR 12187 nodejs.ClusterClientNoResponseError: client no response in 1074984ms exceeding maxIdleTime 60000ms, maybe the connection is close on other side.
    at Timeout._onTimeout (/Users/xujiashuang/Desktop/bigdata-server/node_modules/_cluster-client@3.5.0@cluster-client/lib/leader.js:79:25)
    at listOnTimeout (node:internal/timers:564:17)
    at process.processTimers (node:internal/timers:507:7)
name: "ClusterClientNoResponseError"
pid: 12187
hostname: xjswwdeMBP

2023-10-10 03:46:40,127 ERROR 12187 nodejs.ClusterClientNoResponseError: client no response in 970975ms exceeding maxIdleTime 60000ms, maybe the connection is close on other side.
    at Timeout._onTimeout (/Users/xujiashuang/Desktop/bigdata-server/node_modules/_cluster-client@3.5.0@cluster-client/lib/leader.js:79:25)
    at listOnTimeout (node:internal/timers:564:17)
    at process.processTimers (node:internal/timers:507:7)
name: "ClusterClientNoResponseError"
pid: 12187
hostname: xjswwdeMBP

2023-10-10 04:03:47,082 ERROR 12187 nodejs.ClusterClientNoResponseError: client no response in 1026951ms exceeding maxIdleTime 60000ms, maybe the connection is close on other side.
    at Timeout._onTimeout (/Users/xujiashuang/Desktop/bigdata-server/node_modules/_cluster-client@3.5.0@cluster-client/lib/leader.js:79:25)
    at listOnTimeout (node:internal/timers:564:17)
    at process.processTimers (node:internal/timers:507:7)
name: "ClusterClientNoResponseError"
pid: 12187
hostname: xjswwdeMBP

2023-10-10 04:20:15,057 ERROR 12187 nodejs.ClusterClientNoResponseError: client no response in 987966ms exceeding maxIdleTime 60000ms, maybe the connection is close on other side.
    at Timeout._onTimeout (/Users/xujiashuang/Desktop/bigdata-server/node_modules/_cluster-client@3.5.0@cluster-client/lib/leader.js:79:25)
    at listOnTimeout (node:internal/timers:564:17)
    at process.processTimers (node:internal/timers:507:7)
name: "ClusterClientNoResponseError"
pid: 12187
hostname: xjswwdeMBP

2023-10-10 04:38:15,090 ERROR 12187 nodejs.ClusterClientNoResponseError: client no response in 1080021ms exceeding maxIdleTime 60000ms, maybe the connection is close on other side.
    at Timeout._onTimeout (/Users/xujiashuang/Desktop/bigdata-server/node_modules/_cluster-client@3.5.0@cluster-client/lib/leader.js:79:25)
    at listOnTimeout (node:internal/timers:564:17)
    at process.processTimers (node:internal/timers:507:7)
name: "ClusterClientNoResponseError"
pid: 12187
hostname: xjswwdeMBP

2023-10-10 04:56:07,085 ERROR 12187 nodejs.ClusterClientNoResponseError: client no response in 1071973ms exceeding maxIdleTime 60000ms, maybe the connection is close on other side.
    at Timeout._onTimeout (/Users/xujiashuang/Desktop/bigdata-server/node_modules/_cluster-client@3.5.0@cluster-client/lib/leader.js:79:25)
    at listOnTimeout (node:internal/timers:564:17)
    at process.processTimers (node:internal/timers:507:7)
name: "ClusterClientNoResponseError"
pid: 12187
hostname: xjswwdeMBP

2023-10-10 05:12:42,161 ERROR 12187 nodejs.ClusterClientNoResponseError: client no response in 995074ms exceeding maxIdleTime 60000ms, maybe the connection is close on other side.
    at Timeout._onTimeout (/Users/xujiashuang/Desktop/bigdata-server/node_modules/_cluster-client@3.5.0@cluster-client/lib/leader.js:79:25)
    at listOnTimeout (node:internal/timers:564:17)
    at process.processTimers (node:internal/timers:507:7)
name: "ClusterClientNoResponseError"
pid: 12187
hostname: xjswwdeMBP

2023-10-10 05:29:44,127 ERROR 12187 nodejs.ClusterClientNoResponseError: client no response in 1021959ms exceeding maxIdleTime 60000ms, maybe the connection is close on other side.
    at Timeout._onTimeout (/Users/xujiashuang/Desktop/bigdata-server/node_modules/_cluster-client@3.5.0@cluster-client/lib/leader.js:79:25)
    at listOnTimeout (node:internal/timers:564:17)
    at process.processTimers (node:internal/timers:507:7)
name: "ClusterClientNoResponseError"
pid: 12187
hostname: xjswwdeMBP

2023-10-10 05:46:31,171 ERROR 12187 nodejs.ClusterClientNoResponseError: client no response in 1007038ms exceeding maxIdleTime 60000ms, maybe the connection is close on other side.
    at Timeout._onTimeout (/Users/xujiashuang/Desktop/bigdata-server/node_modules/_cluster-client@3.5.0@cluster-client/lib/leader.js:79:25)
    at listOnTimeout (node:internal/timers:564:17)
    at process.processTimers (node:internal/timers:507:7)
name: "ClusterClientNoResponseError"
pid: 12187
hostname: xjswwdeMBP

2023-10-10 06:03:37,171 ERROR 12187 nodejs.ClusterClientNoResponseError: client no response in 1025993ms exceeding maxIdleTime 60000ms, maybe the connection is close on other side.
    at Timeout._onTimeout (/Users/xujiashuang/Desktop/bigdata-server/node_modules/_cluster-client@3.5.0@cluster-client/lib/leader.js:79:25)
    at listOnTimeout (node:internal/timers:564:17)
    at process.processTimers (node:internal/timers:507:7)
name: "ClusterClientNoResponseError"
pid: 12187
hostname: xjswwdeMBP

2023-10-10 06:19:04,092 ERROR 12187 nodejs.ClusterClientNoResponseError: client no response in 926912ms exceeding maxIdleTime 60000ms, maybe the connection is close on other side.
    at Timeout._onTimeout (/Users/xujiashuang/Desktop/bigdata-server/node_modules/_cluster-client@3.5.0@cluster-client/lib/leader.js:79:25)
    at listOnTimeout (node:internal/timers:564:17)
    at process.processTimers (node:internal/timers:507:7)
name: "ClusterClientNoResponseError"
pid: 12187
hostname: xjswwdeMBP

2023-10-10 06:35:01,194 ERROR 12187 nodejs.ClusterClientNoResponseError: client no response in 957095ms exceeding maxIdleTime 60000ms, maybe the connection is close on other side.
    at Timeout._onTimeout (/Users/xujiashuang/Desktop/bigdata-server/node_modules/_cluster-client@3.5.0@cluster-client/lib/leader.js:79:25)
    at listOnTimeout (node:internal/timers:564:17)
    at process.processTimers (node:internal/timers:507:7)
name: "ClusterClientNoResponseError"
pid: 12187
hostname: xjswwdeMBP

2023-10-10 06:51:43,853 ERROR 12187 nodejs.ClusterClientNoResponseError: client no response in 1002655ms exceeding maxIdleTime 60000ms, maybe the connection is close on other side.
    at Timeout._onTimeout (/Users/xujiashuang/Desktop/bigdata-server/node_modules/_cluster-client@3.5.0@cluster-client/lib/leader.js:79:25)
    at listOnTimeout (node:internal/timers:564:17)
    at process.processTimers (node:internal/timers:507:7)
name: "ClusterClientNoResponseError"
pid: 12187
hostname: xjswwdeMBP

2023-10-10 07:07:39,842 ERROR 12187 nodejs.ClusterClientNoResponseError: client no response in 955986ms exceeding maxIdleTime 60000ms, maybe the connection is close on other side.
    at Timeout._onTimeout (/Users/xujiashuang/Desktop/bigdata-server/node_modules/_cluster-client@3.5.0@cluster-client/lib/leader.js:79:25)
    at listOnTimeout (node:internal/timers:564:17)
    at process.processTimers (node:internal/timers:507:7)
name: "ClusterClientNoResponseError"
pid: 12187
hostname: xjswwdeMBP

2023-10-10 07:24:55,792 ERROR 12187 nodejs.ClusterClientNoResponseError: client no response in 1035949ms exceeding maxIdleTime 60000ms, maybe the connection is close on other side.
    at Timeout._onTimeout (/Users/xujiashuang/Desktop/bigdata-server/node_modules/_cluster-client@3.5.0@cluster-client/lib/leader.js:79:25)
    at listOnTimeout (node:internal/timers:564:17)
    at process.processTimers (node:internal/timers:507:7)
name: "ClusterClientNoResponseError"
pid: 12187
hostname: xjswwdeMBP

2023-10-10 07:41:09,818 ERROR 12187 nodejs.ClusterClientNoResponseError: client no response in 974023ms exceeding maxIdleTime 60000ms, maybe the connection is close on other side.
    at Timeout._onTimeout (/Users/xujiashuang/Desktop/bigdata-server/node_modules/_cluster-client@3.5.0@cluster-client/lib/leader.js:79:25)
    at listOnTimeout (node:internal/timers:564:17)
    at process.processTimers (node:internal/timers:507:7)
name: "ClusterClientNoResponseError"
pid: 12187
hostname: xjswwdeMBP

2023-10-10 07:57:49,849 ERROR 12187 nodejs.ClusterClientNoResponseError: client no response in 1000028ms exceeding maxIdleTime 60000ms, maybe the connection is close on other side.
    at Timeout._onTimeout (/Users/xujiashuang/Desktop/bigdata-server/node_modules/_cluster-client@3.5.0@cluster-client/lib/leader.js:79:25)
    at listOnTimeout (node:internal/timers:564:17)
    at process.processTimers (node:internal/timers:507:7)
name: "ClusterClientNoResponseError"
pid: 12187
hostname: xjswwdeMBP

2023-10-10 08:12:56,872 ERROR 12187 nodejs.ClusterClientNoResponseError: client no response in 907022ms exceeding maxIdleTime 60000ms, maybe the connection is close on other side.
    at Timeout._onTimeout (/Users/xujiashuang/Desktop/bigdata-server/node_modules/_cluster-client@3.5.0@cluster-client/lib/leader.js:79:25)
    at listOnTimeout (node:internal/timers:564:17)
    at process.processTimers (node:internal/timers:507:7)
name: "ClusterClientNoResponseError"
pid: 12187
hostname: xjswwdeMBP

2023-10-10 08:45:56,849 ERROR 12187 nodejs.ClusterClientNoResponseError: client no response in 1070983ms exceeding maxIdleTime 60000ms, maybe the connection is close on other side.
    at Timeout._onTimeout (/Users/xujiashuang/Desktop/bigdata-server/node_modules/_cluster-client@3.5.0@cluster-client/lib/leader.js:79:25)
    at listOnTimeout (node:internal/timers:564:17)
    at process.processTimers (node:internal/timers:507:7)
name: "ClusterClientNoResponseError"
pid: 12187
hostname: xjswwdeMBP

2023-10-10 08:49:03,819 ERROR 12187 nodejs.ClusterClientNoResponseError: client no response in 186965ms exceeding maxIdleTime 60000ms, maybe the connection is close on other side.
    at Timeout._onTimeout (/Users/xujiashuang/Desktop/bigdata-server/node_modules/_cluster-client@3.5.0@cluster-client/lib/leader.js:79:25)
    at listOnTimeout (node:internal/timers:564:17)
    at process.processTimers (node:internal/timers:507:7)
name: "ClusterClientNoResponseError"
pid: 12187
hostname: xjswwdeMBP

2023-10-10 08:50:07,337 ERROR 12187 nodejs.ClusterClientNoResponseError: client no response in 63514ms exceeding maxIdleTime 60000ms, maybe the connection is close on other side.
    at Timeout._onTimeout (/Users/xujiashuang/Desktop/bigdata-server/node_modules/_cluster-client@3.5.0@cluster-client/lib/leader.js:79:25)
    at listOnTimeout (node:internal/timers:564:17)
    at process.processTimers (node:internal/timers:507:7)
name: "ClusterClientNoResponseError"
pid: 12187
hostname: xjswwdeMBP

2023-10-10 09:01:01,736 ERROR 22799 [-/127.0.0.1/-/60ms POST /api/report/list] nodejs.ER_NO_SUCH_TABLEError: ER_NO_SUCH_TABLE: Table 'bigdata_period.bigdata_period' doesn't exist
    at Sequence._packetToError (/Users/xujiashuang/Desktop/bigdata-server/node_modules/_mysql@2.18.1@mysql/lib/protocol/sequences/Sequence.js:47:14)
    at Query.ErrorPacket (/Users/xujiashuang/Desktop/bigdata-server/node_modules/_mysql@2.18.1@mysql/lib/protocol/sequences/Query.js:79:18)
    at Protocol._parsePacket (/Users/xujiashuang/Desktop/bigdata-server/node_modules/_mysql@2.18.1@mysql/lib/protocol/Protocol.js:291:23)
    at Parser._parsePacket (/Users/xujiashuang/Desktop/bigdata-server/node_modules/_mysql@2.18.1@mysql/lib/protocol/Parser.js:433:10)
    at Parser.write (/Users/xujiashuang/Desktop/bigdata-server/node_modules/_mysql@2.18.1@mysql/lib/protocol/Parser.js:43:10)
    at Protocol.write (/Users/xujiashuang/Desktop/bigdata-server/node_modules/_mysql@2.18.1@mysql/lib/protocol/Protocol.js:38:16)
    at Socket.<anonymous> (/Users/xujiashuang/Desktop/bigdata-server/node_modules/_mysql@2.18.1@mysql/lib/Connection.js:88:28)
    at Socket.<anonymous> (/Users/xujiashuang/Desktop/bigdata-server/node_modules/_mysql@2.18.1@mysql/lib/Connection.js:526:10)
    at Socket.emit (node:events:527:28)
    at addChunk (node:internal/streams/readable:324:12)
    --------------------
    at Pool.query (/Users/xujiashuang/Desktop/bigdata-server/node_modules/_mysql@2.18.1@mysql/lib/Pool.js:199:23)
    at node:internal/util:360:7
    at new Promise (<anonymous>)
    at Pool.query (node:internal/util:346:12)
    at RDSClient._query (/Users/xujiashuang/Desktop/bigdata-server/node_modules/_ali-rds@5.1.2@ali-rds/lib/client.js:33:33)
    at RDSClient.query (/Users/xujiashuang/Desktop/bigdata-server/node_modules/_ali-rds@5.1.2@ali-rds/lib/operator.js:62:31)
    at /Users/xujiashuang/Desktop/bigdata-server/app/service/bigdata.js:23:39
    at new Promise (<anonymous>)
    at BigDataService.getReportList (/Users/xujiashuang/Desktop/bigdata-server/app/service/bigdata.js:11:10)
    at BigDataController.getReportList (/Users/xujiashuang/Desktop/bigdata-server/app/controller/bigdata.js:8:40)
    sql: select * from bigdata_period where reportType = 3 order by createTime desc limit 0,10
code: "ER_NO_SUCH_TABLE"
errno: 1146
sqlMessage: "Table 'bigdata_period.bigdata_period' doesn't exist"
sqlState: "42S02"
index: 0
sql: "select * from bigdata_period where reportType = 3 order by createTime desc limit 0,10"
headers: {"Access-Control-Allow-Origin":"*","vary":"Origin"}
name: "ER_NO_SUCH_TABLEError"
pid: 22799
hostname: xjswwdeMBP

2023-10-10 09:37:13,898 ERROR 23667 [-/127.0.0.1/-/9ms POST /api/report/createtask] nodejs.ER_BAD_FIELD_ERRORError: ER_BAD_FIELD_ERROR: Unknown column 'priority' in 'field list'
    at Sequence._packetToError (/Users/xujiashuang/Desktop/bigdata-server/node_modules/_mysql@2.18.1@mysql/lib/protocol/sequences/Sequence.js:47:14)
    at Query.ErrorPacket (/Users/xujiashuang/Desktop/bigdata-server/node_modules/_mysql@2.18.1@mysql/lib/protocol/sequences/Query.js:79:18)
    at Protocol._parsePacket (/Users/xujiashuang/Desktop/bigdata-server/node_modules/_mysql@2.18.1@mysql/lib/protocol/Protocol.js:291:23)
    at Parser._parsePacket (/Users/xujiashuang/Desktop/bigdata-server/node_modules/_mysql@2.18.1@mysql/lib/protocol/Parser.js:433:10)
    at Parser.write (/Users/xujiashuang/Desktop/bigdata-server/node_modules/_mysql@2.18.1@mysql/lib/protocol/Parser.js:43:10)
    at Protocol.write (/Users/xujiashuang/Desktop/bigdata-server/node_modules/_mysql@2.18.1@mysql/lib/protocol/Protocol.js:38:16)
    at Socket.<anonymous> (/Users/xujiashuang/Desktop/bigdata-server/node_modules/_mysql@2.18.1@mysql/lib/Connection.js:88:28)
    at Socket.<anonymous> (/Users/xujiashuang/Desktop/bigdata-server/node_modules/_mysql@2.18.1@mysql/lib/Connection.js:526:10)
    at Socket.emit (node:events:527:28)
    at addChunk (node:internal/streams/readable:324:12)
    --------------------
    at Pool.query (/Users/xujiashuang/Desktop/bigdata-server/node_modules/_mysql@2.18.1@mysql/lib/Pool.js:199:23)
    at node:internal/util:360:7
    at new Promise (<anonymous>)
    at Pool.query (node:internal/util:346:12)
    at RDSClient._query (/Users/xujiashuang/Desktop/bigdata-server/node_modules/_ali-rds@5.1.2@ali-rds/lib/client.js:33:33)
    at RDSClient.query (/Users/xujiashuang/Desktop/bigdata-server/node_modules/_ali-rds@5.1.2@ali-rds/lib/operator.js:62:31)
    at RDSClient.insert (/Users/xujiashuang/Desktop/bigdata-server/node_modules/_ali-rds@5.1.2@ali-rds/lib/operator.js:159:27)
    at /Users/xujiashuang/Desktop/bigdata-server/app/service/bigdata.js:110:41
    at new Promise (<anonymous>)
    at BigDataService.createTask (/Users/xujiashuang/Desktop/bigdata-server/app/service/bigdata.js:108:10)
    sql: INSERT INTO `report_list`(`reportName`, `LargeCategory`, `TimeOn`, `endTime`, `priority`, `createTime`) VALUES('test', '周期性', '2023-10-10T00:00:00+08:00', '2023-12-20T00:00:00+08:00', 99, '2023-10-10 09:37:13.889')
code: "ER_BAD_FIELD_ERROR"
errno: 1054
sqlMessage: "Unknown column 'priority' in 'field list'"
sqlState: "42S22"
index: 0
sql: "INSERT INTO `report_list`(`reportName`, `LargeCategory`, `TimeOn`, `endTime`, `priority`, `createTime`) VALUES('test', '周期性', '2023-10-10T00:00:00+08:00', '2023-12-20T00:00:00+08:00', 99, '2023-10-10 09:37:13.889')"
headers: {"Access-Control-Allow-Origin":"*","vary":"Origin"}
name: "ER_BAD_FIELD_ERRORError"
pid: 23667
hostname: xjswwdeMBP

2023-10-10 09:44:18,023 ERROR 23667 [-/127.0.0.1/-/72ms POST /api/report/list] nodejs.ER_NO_SUCH_TABLEError: ER_NO_SUCH_TABLE: Table 'bigdata_period.bigdata_period' doesn't exist
    at Sequence._packetToError (/Users/xujiashuang/Desktop/bigdata-server/node_modules/_mysql@2.18.1@mysql/lib/protocol/sequences/Sequence.js:47:14)
    at Query.ErrorPacket (/Users/xujiashuang/Desktop/bigdata-server/node_modules/_mysql@2.18.1@mysql/lib/protocol/sequences/Query.js:79:18)
    at Protocol._parsePacket (/Users/xujiashuang/Desktop/bigdata-server/node_modules/_mysql@2.18.1@mysql/lib/protocol/Protocol.js:291:23)
    at Parser._parsePacket (/Users/xujiashuang/Desktop/bigdata-server/node_modules/_mysql@2.18.1@mysql/lib/protocol/Parser.js:433:10)
    at Parser.write (/Users/xujiashuang/Desktop/bigdata-server/node_modules/_mysql@2.18.1@mysql/lib/protocol/Parser.js:43:10)
    at Protocol.write (/Users/xujiashuang/Desktop/bigdata-server/node_modules/_mysql@2.18.1@mysql/lib/protocol/Protocol.js:38:16)
    at Socket.<anonymous> (/Users/xujiashuang/Desktop/bigdata-server/node_modules/_mysql@2.18.1@mysql/lib/Connection.js:88:28)
    at Socket.<anonymous> (/Users/xujiashuang/Desktop/bigdata-server/node_modules/_mysql@2.18.1@mysql/lib/Connection.js:526:10)
    at Socket.emit (node:events:527:28)
    at addChunk (node:internal/streams/readable:324:12)
    --------------------
    at Pool.query (/Users/xujiashuang/Desktop/bigdata-server/node_modules/_mysql@2.18.1@mysql/lib/Pool.js:199:23)
    at node:internal/util:360:7
    at new Promise (<anonymous>)
    at Pool.query (node:internal/util:346:12)
    at RDSClient._query (/Users/xujiashuang/Desktop/bigdata-server/node_modules/_ali-rds@5.1.2@ali-rds/lib/client.js:33:33)
    at RDSClient.query (/Users/xujiashuang/Desktop/bigdata-server/node_modules/_ali-rds@5.1.2@ali-rds/lib/operator.js:62:31)
    at /Users/xujiashuang/Desktop/bigdata-server/app/service/bigdata.js:23:39
    at new Promise (<anonymous>)
    at BigDataService.getReportList (/Users/xujiashuang/Desktop/bigdata-server/app/service/bigdata.js:11:10)
    at BigDataController.getReportList (/Users/xujiashuang/Desktop/bigdata-server/app/controller/bigdata.js:8:40)
    sql: select * from bigdata_period where reportType = 3 order by createTime desc limit 0,10
code: "ER_NO_SUCH_TABLE"
errno: 1146
sqlMessage: "Table 'bigdata_period.bigdata_period' doesn't exist"
sqlState: "42S02"
index: 0
sql: "select * from bigdata_period where reportType = 3 order by createTime desc limit 0,10"
headers: {"Access-Control-Allow-Origin":"*","vary":"Origin"}
name: "ER_NO_SUCH_TABLEError"
pid: 23667
hostname: xjswwdeMBP

2023-10-10 10:38:55,149 ERROR 25947 [-/127.0.0.1/-/19ms POST /api/report/addsql] nodejs.TypeError: Cannot create property 'headers' on string '没有任务id'
    at cors (/Users/xujiashuang/Desktop/bigdata-server/node_modules/_@koa_cors@3.4.3@@koa/cors/index.js:116:21)
    at process.processTicksAndRejections (node:internal/process/task_queues:95:5)
    at async /Users/xujiashuang/Desktop/bigdata-server/node_modules/_koa@2.14.2@koa/lib/application.js:160:16

pid: 25947
hostname: xjswwdeMBP

2023-10-10 10:43:23,643 ERROR 26035 [-/127.0.0.1/-/9ms POST /api/report/createtask] nodejs.ER_BAD_FIELD_ERRORError: ER_BAD_FIELD_ERROR: Unknown column 'priority' in 'field list'
    at Sequence._packetToError (/Users/xujiashuang/Desktop/bigdata-server/node_modules/_mysql@2.18.1@mysql/lib/protocol/sequences/Sequence.js:47:14)
    at Query.ErrorPacket (/Users/xujiashuang/Desktop/bigdata-server/node_modules/_mysql@2.18.1@mysql/lib/protocol/sequences/Query.js:79:18)
    at Protocol._parsePacket (/Users/xujiashuang/Desktop/bigdata-server/node_modules/_mysql@2.18.1@mysql/lib/protocol/Protocol.js:291:23)
    at Parser._parsePacket (/Users/xujiashuang/Desktop/bigdata-server/node_modules/_mysql@2.18.1@mysql/lib/protocol/Parser.js:433:10)
    at Parser.write (/Users/xujiashuang/Desktop/bigdata-server/node_modules/_mysql@2.18.1@mysql/lib/protocol/Parser.js:43:10)
    at Protocol.write (/Users/xujiashuang/Desktop/bigdata-server/node_modules/_mysql@2.18.1@mysql/lib/protocol/Protocol.js:38:16)
    at Socket.<anonymous> (/Users/xujiashuang/Desktop/bigdata-server/node_modules/_mysql@2.18.1@mysql/lib/Connection.js:88:28)
    at Socket.<anonymous> (/Users/xujiashuang/Desktop/bigdata-server/node_modules/_mysql@2.18.1@mysql/lib/Connection.js:526:10)
    at Socket.emit (node:events:527:28)
    at addChunk (node:internal/streams/readable:324:12)
    --------------------
    at Pool.query (/Users/xujiashuang/Desktop/bigdata-server/node_modules/_mysql@2.18.1@mysql/lib/Pool.js:199:23)
    at node:internal/util:360:7
    at new Promise (<anonymous>)
    at Pool.query (node:internal/util:346:12)
    at RDSClient._query (/Users/xujiashuang/Desktop/bigdata-server/node_modules/_ali-rds@5.1.2@ali-rds/lib/client.js:33:33)
    at RDSClient.query (/Users/xujiashuang/Desktop/bigdata-server/node_modules/_ali-rds@5.1.2@ali-rds/lib/operator.js:62:31)
    at RDSClient.insert (/Users/xujiashuang/Desktop/bigdata-server/node_modules/_ali-rds@5.1.2@ali-rds/lib/operator.js:159:27)
    at /Users/xujiashuang/Desktop/bigdata-server/app/service/bigdata.js:110:41
    at new Promise (<anonymous>)
    at BigDataService.createTask (/Users/xujiashuang/Desktop/bigdata-server/app/service/bigdata.js:108:10)
    sql: INSERT INTO `report_list`(`reportName`, `LargeCategory`, `TimeOn`, `endTime`, `priority`, `createTime`) VALUES('测试流程', '周期性', '2023-10-10T00:00:00+08:00', '2024-11-10T00:00:00+08:00', 99, '2023-10-10 10:43:23.635')
code: "ER_BAD_FIELD_ERROR"
errno: 1054
sqlMessage: "Unknown column 'priority' in 'field list'"
sqlState: "42S22"
index: 0
sql: "INSERT INTO `report_list`(`reportName`, `LargeCategory`, `TimeOn`, `endTime`, `priority`, `createTime`) VALUES('测试流程', '周期性', '2023-10-10T00:00:00+08:00', '2024-11-10T00:00:00+08:00', 99, '2023-10-10 10:43:23.635')"
headers: {"Access-Control-Allow-Origin":"*","vary":"Origin"}
name: "ER_BAD_FIELD_ERRORError"
pid: 26035
hostname: xjswwdeMBP

2023-10-10 11:11:44,394 ERROR 26035 [-/127.0.0.1/-/37ms POST /api/report/sqllist] nodejs.unhandledRejectionError: ER_NO_SUCH_TABLE: Table 'bigdata_period.sql_data' doesn't exist
    at Sequence._packetToError (/Users/xujiashuang/Desktop/bigdata-server/node_modules/_mysql@2.18.1@mysql/lib/protocol/sequences/Sequence.js:47:14)
    at Query.ErrorPacket (/Users/xujiashuang/Desktop/bigdata-server/node_modules/_mysql@2.18.1@mysql/lib/protocol/sequences/Query.js:79:18)
    at Protocol._parsePacket (/Users/xujiashuang/Desktop/bigdata-server/node_modules/_mysql@2.18.1@mysql/lib/protocol/Protocol.js:291:23)
    at Parser._parsePacket (/Users/xujiashuang/Desktop/bigdata-server/node_modules/_mysql@2.18.1@mysql/lib/protocol/Parser.js:433:10)
    at Parser.write (/Users/xujiashuang/Desktop/bigdata-server/node_modules/_mysql@2.18.1@mysql/lib/protocol/Parser.js:43:10)
    at Protocol.write (/Users/xujiashuang/Desktop/bigdata-server/node_modules/_mysql@2.18.1@mysql/lib/protocol/Protocol.js:38:16)
    at Socket.<anonymous> (/Users/xujiashuang/Desktop/bigdata-server/node_modules/_mysql@2.18.1@mysql/lib/Connection.js:88:28)
    at Socket.<anonymous> (/Users/xujiashuang/Desktop/bigdata-server/node_modules/_mysql@2.18.1@mysql/lib/Connection.js:526:10)
    at Socket.emit (node:events:527:28)
    at addChunk (node:internal/streams/readable:324:12)
    --------------------
    at Pool.query (/Users/xujiashuang/Desktop/bigdata-server/node_modules/_mysql@2.18.1@mysql/lib/Pool.js:199:23)
    at node:internal/util:360:7
    at new Promise (<anonymous>)
    at Pool.query (node:internal/util:346:12)
    at RDSClient._query (/Users/xujiashuang/Desktop/bigdata-server/node_modules/_ali-rds@5.1.2@ali-rds/lib/client.js:33:33)
    at RDSClient.query (/Users/xujiashuang/Desktop/bigdata-server/node_modules/_ali-rds@5.1.2@ali-rds/lib/operator.js:62:31)
    at /Users/xujiashuang/Desktop/bigdata-server/app/service/bigdata.js:91:57
    at new Promise (<anonymous>)
    at BigDataService.getSQL (/Users/xujiashuang/Desktop/bigdata-server/app/service/bigdata.js:87:10)
    at BigDataController.getSQL (/Users/xujiashuang/Desktop/bigdata-server/app/controller/bigdata.js:14:40)
    sql: SELECT COUNT(*) from sql_Data 
code: "ER_NO_SUCH_TABLE"
errno: 1146
sqlMessage: "Table 'bigdata_period.sql_data' doesn't exist"
sqlState: "42S02"
index: 0
sql: "SELECT COUNT(*) from sql_Data "
name: "unhandledRejectionError"
pid: 26035
hostname: xjswwdeMBP

2023-10-10 11:11:51,436 ERROR 26035 [-/127.0.0.1/-/4ms POST /api/report/sqllist] nodejs.unhandledRejectionError: ER_NO_SUCH_TABLE: Table 'bigdata_period.sql_data' doesn't exist
    at Sequence._packetToError (/Users/xujiashuang/Desktop/bigdata-server/node_modules/_mysql@2.18.1@mysql/lib/protocol/sequences/Sequence.js:47:14)
    at Query.ErrorPacket (/Users/xujiashuang/Desktop/bigdata-server/node_modules/_mysql@2.18.1@mysql/lib/protocol/sequences/Query.js:79:18)
    at Protocol._parsePacket (/Users/xujiashuang/Desktop/bigdata-server/node_modules/_mysql@2.18.1@mysql/lib/protocol/Protocol.js:291:23)
    at Parser._parsePacket (/Users/xujiashuang/Desktop/bigdata-server/node_modules/_mysql@2.18.1@mysql/lib/protocol/Parser.js:433:10)
    at Parser.write (/Users/xujiashuang/Desktop/bigdata-server/node_modules/_mysql@2.18.1@mysql/lib/protocol/Parser.js:43:10)
    at Protocol.write (/Users/xujiashuang/Desktop/bigdata-server/node_modules/_mysql@2.18.1@mysql/lib/protocol/Protocol.js:38:16)
    at Socket.<anonymous> (/Users/xujiashuang/Desktop/bigdata-server/node_modules/_mysql@2.18.1@mysql/lib/Connection.js:88:28)
    at Socket.<anonymous> (/Users/xujiashuang/Desktop/bigdata-server/node_modules/_mysql@2.18.1@mysql/lib/Connection.js:526:10)
    at Socket.emit (node:events:527:28)
    at addChunk (node:internal/streams/readable:324:12)
    --------------------
    at Pool.query (/Users/xujiashuang/Desktop/bigdata-server/node_modules/_mysql@2.18.1@mysql/lib/Pool.js:199:23)
    at node:internal/util:360:7
    at new Promise (<anonymous>)
    at Pool.query (node:internal/util:346:12)
    at RDSClient._query (/Users/xujiashuang/Desktop/bigdata-server/node_modules/_ali-rds@5.1.2@ali-rds/lib/client.js:33:33)
    at RDSClient.query (/Users/xujiashuang/Desktop/bigdata-server/node_modules/_ali-rds@5.1.2@ali-rds/lib/operator.js:62:31)
    at /Users/xujiashuang/Desktop/bigdata-server/app/service/bigdata.js:91:57
    at new Promise (<anonymous>)
    at BigDataService.getSQL (/Users/xujiashuang/Desktop/bigdata-server/app/service/bigdata.js:87:10)
    at BigDataController.getSQL (/Users/xujiashuang/Desktop/bigdata-server/app/controller/bigdata.js:14:40)
    sql: SELECT COUNT(*) from sql_Data 
code: "ER_NO_SUCH_TABLE"
errno: 1146
sqlMessage: "Table 'bigdata_period.sql_data' doesn't exist"
sqlState: "42S02"
index: 0
sql: "SELECT COUNT(*) from sql_Data "
name: "unhandledRejectionError"
pid: 26035
hostname: xjswwdeMBP

2023-10-10 11:54:38,443 ERROR 22795 nodejs.ClusterClientNoResponseError: client no response in 1012914ms exceeding maxIdleTime 60000ms, maybe the connection is close on other side.
    at Timeout._onTimeout (/Users/xujiashuang/Desktop/bigdata-server/node_modules/_cluster-client@3.5.0@cluster-client/lib/leader.js:79:25)
    at listOnTimeout (node:internal/timers:564:17)
    at process.processTimers (node:internal/timers:507:7)
name: "ClusterClientNoResponseError"
pid: 22795
hostname: xjswwdeMBP

2023-10-10 12:09:43,395 ERROR 22795 nodejs.ClusterClientNoResponseError: client no response in 904841ms exceeding maxIdleTime 60000ms, maybe the connection is close on other side.
    at Timeout._onTimeout (/Users/xujiashuang/Desktop/bigdata-server/node_modules/_cluster-client@3.5.0@cluster-client/lib/leader.js:79:25)
    at listOnTimeout (node:internal/timers:564:17)
    at process.processTimers (node:internal/timers:507:7)
name: "ClusterClientNoResponseError"
pid: 22795
hostname: xjswwdeMBP

2023-10-10 12:20:43,496 ERROR 22795 nodejs.ClusterClientNoResponseError: client no response in 660099ms exceeding maxIdleTime 60000ms, maybe the connection is close on other side.
    at Timeout._onTimeout (/Users/xujiashuang/Desktop/bigdata-server/node_modules/_cluster-client@3.5.0@cluster-client/lib/leader.js:79:25)
    at listOnTimeout (node:internal/timers:564:17)
    at process.processTimers (node:internal/timers:507:7)
name: "ClusterClientNoResponseError"
pid: 22795
hostname: xjswwdeMBP

2023-10-10 14:26:47,399 ERROR 22795 nodejs.ClusterClientNoResponseError: client no response in 222429ms exceeding maxIdleTime 60000ms, maybe the connection is close on other side.
    at Timeout._onTimeout (/Users/xujiashuang/Desktop/bigdata-server/node_modules/_cluster-client@3.5.0@cluster-client/lib/leader.js:79:25)
    at listOnTimeout (node:internal/timers:564:17)
    at process.processTimers (node:internal/timers:507:7)
name: "ClusterClientNoResponseError"
pid: 22795
hostname: xjswwdeMBP

2023-10-10 14:59:59,723 ERROR 30737 [-/127.0.0.1/-/26ms SCHEDULE /__schedule?path=/Users/xujiashuang/Desktop/bigdata-server/app/schedule/checkTaskStatus.js&cron=0%200%2015%20*%20*%20%3F&type=worker] [Job#169692119965310586153809880411] /Users/xujiashuang/Desktop/bigdata-server/app/schedule/checkTaskStatus.js execute failed, used 22ms. Error: ER_NO_SUCH_TABLE: Table 'bigdata_period.subtask_list' doesn't exist
    at Sequence._packetToError (/Users/xujiashuang/Desktop/bigdata-server/node_modules/_mysql@2.18.1@mysql/lib/protocol/sequences/Sequence.js:47:14)
    at Query.ErrorPacket (/Users/xujiashuang/Desktop/bigdata-server/node_modules/_mysql@2.18.1@mysql/lib/protocol/sequences/Query.js:79:18)
    at Protocol._parsePacket (/Users/xujiashuang/Desktop/bigdata-server/node_modules/_mysql@2.18.1@mysql/lib/protocol/Protocol.js:291:23)
    at Parser._parsePacket (/Users/xujiashuang/Desktop/bigdata-server/node_modules/_mysql@2.18.1@mysql/lib/protocol/Parser.js:433:10)
    at Parser.write (/Users/xujiashuang/Desktop/bigdata-server/node_modules/_mysql@2.18.1@mysql/lib/protocol/Parser.js:43:10)
    at Protocol.write (/Users/xujiashuang/Desktop/bigdata-server/node_modules/_mysql@2.18.1@mysql/lib/protocol/Protocol.js:38:16)
    at Socket.<anonymous> (/Users/xujiashuang/Desktop/bigdata-server/node_modules/_mysql@2.18.1@mysql/lib/Connection.js:88:28)
    at Socket.<anonymous> (/Users/xujiashuang/Desktop/bigdata-server/node_modules/_mysql@2.18.1@mysql/lib/Connection.js:526:10)
    at Socket.emit (node:events:527:28)
    at addChunk (node:internal/streams/readable:324:12)
    --------------------
    at Pool.query (/Users/xujiashuang/Desktop/bigdata-server/node_modules/_mysql@2.18.1@mysql/lib/Pool.js:199:23)
    at node:internal/util:360:7
    at new Promise (<anonymous>)
    at Pool.query (node:internal/util:346:12)
    at RDSClient._query (/Users/xujiashuang/Desktop/bigdata-server/node_modules/_ali-rds@5.1.2@ali-rds/lib/client.js:33:33)
    at RDSClient.query (/Users/xujiashuang/Desktop/bigdata-server/node_modules/_ali-rds@5.1.2@ali-rds/lib/operator.js:62:31)
    at RDSClient.select (/Users/xujiashuang/Desktop/bigdata-server/node_modules/_ali-rds@5.1.2@ali-rds/lib/operator.js:120:27)
    at logTime.subscribe (/Users/xujiashuang/Desktop/bigdata-server/app/schedule/checkTaskStatus.js:40:37)
    at Object.task (/Users/xujiashuang/Desktop/bigdata-server/node_modules/_egg-schedule@4.0.0@egg-schedule/lib/load_schedule.js:37:22)
    at /Users/xujiashuang/Desktop/bigdata-server/node_modules/_egg-schedule@4.0.0@egg-schedule/app.js:48:23
    sql: SELECT * FROM `subtask_list` WHERE `status` = 3 {
  code: 'ER_NO_SUCH_TABLE',
  errno: 1146,
  sqlMessage: "Table 'bigdata_period.subtask_list' doesn't exist",
  sqlState: '42S02',
  index: 0,
  sql: 'SELECT * FROM `subtask_list` WHERE `status` = 3'
}
